Workbook

Sheet Gantt Chart
A1: ID | B1: Workstream | C1: Task | D1: Start | E1: End | F1: Status | G1: Progress % | H1: Owner | I1: Dependency | J1: Acceptance Criteria | K1: 46148 | L1: 46149 | M1: 46150 | N1: 46151 | O1: 46152 | P1: 46153 | Q1: 46154 | R1: 46155 | S1: 46156 | T1: 46157 | U1: 46158 | V1: 46159 | W1: 46160 | X1: 46161 | Y1: 46162 | Z1: 46163 | AA1: 46164 | AB1: 46165 | AC1: 46166 | AD1: 46167 | AE1: 46168 | AF1: 46169 | AG1: 46170 | AH1: 46171 | AI1: 46172 | AJ1: 46173 | AK1: 46174 | AL1: 46175 | AM1: 46176 | AN1: 46177 | AO1: 46178 | AP1: 46179 | AQ1: 46180 | AR1: 46181 | AS1: 46182 | AT1: 46183 | AU1: 46184 | AV1: 46185 | AW1: 46186 | AX1: 46187 | AY1: 46188 | AZ1: 46189 | BA1: 46190 | BB1: 46191 | BC1: 46192 | BD1: 46193 | BE1: 46194 | BF1: 46195 | BG1: 46196 | BH1: 46197 | BI1: 46198 | BJ1: 46199 | BK1: 46200 | BL1: 46201 | BM1: 46202 | BN1: 46203 | BO1: 46204 | BP1: 46205 | BQ1: 46206 | BR1: 46207 | BS1: 46208 | BT1: 46209 | BU1: 46210 | BV1: 46211 | BW1: 46212 | BX1: 46213 | BY1: 46214 | BZ1: 46215 | CA1: 46216 | CB1: 46217 | CC1: 46218 | CD1: 46219 | CE1: 46220 | CF1: 46221 | CG1: 46222 | CH1: 46223 | CI1: 46224 | CJ1: 46225 | CK1: 46226 | CL1: 46227 | CM1: 46228 | CN1: 46229 | CO1: 46230 | CP1: 46231 | CQ1: 46232 | CR1: 46233 | CS1: 46234 | CT1: 46235 | CU1: 46236 | CV1: 46237 | CW1: 46238 | CX1: 46239 | CY1: 46240 | CZ1: 46241 | DA1: 46242 | DB1: 46243 | DC1: 46244 | DD1: 46245 | DE1: 46246 | DF1: 46247 | DG1: 46248 | DH1: 46249 | DI1: 46250 | DJ1: 46251 | DK1: 46252 | DL1: 46253 | DM1: 46254 | DN1: 46255 | DO1: 46256 | DP1: 46257 | DQ1: 46258 | DR1: 46259 | DS1: 46260 | DT1: 46261 | DU1: 46262 | DV1: 46263 | DW1: 46264 | DX1: 46265 | DY1: 46266 | DZ1: 46267 | EA1: 46268 | EB1: 46269 | EC1: 46270 | ED1: 46271 | EE1: 46272 | EF1: 46273 | EG1: 46274 | EH1: 46275 | EI1: 46276 | EJ1: 46277 | EK1: 46278 | EL1: 46279 | EM1: 46280 | EN1: 46281 | EO1: 46282 | EP1: 46283 | EQ1: 46284 | ER1: 46285 | ES1: 46286 | ET1: 46287 | EU1: 46288 | EV1: 46289 | EW1: 46290 | EX1: 46291 | EY1: 46292 | EZ1: 46293 | FA1: 46294 | FB1: 46295 | FC1: 46296 | FD1: 46297 | FE1: 46298 | FF1: 46299 | FG1: 46300 | FH1: 46301 | FI1: 46302 | FJ1: 46303 | FK1: 46304 | FL1: 46305 | FM1: 46306 | FN1: 46307 | FO1: 46308 | FP1: 46309 | FQ1: 46310 | FR1: 46311 | FS1: 46312 | FT1: 46313 | FU1: 46314 | FV1: 46315 | FW1: 46316 | FX1: 46317 | FY1: 工时版 | FZ1: 备注
A2: P0 | B2: 启动 | C2: 基线、风险、计划 | D2: 46148 | E2: 46151 | F2: pending | G2: 0 | I2: 无 | J2: baseline + risk list 完成 | FY2: 见 Hourly Gantt：按每日计划工时展示，当前默认 10h/日级任务，并汇总完成/剩余工时。 | FZ2: 见 Hourly Gantt：按每日计划工时展示，当前默认 10h/日级任务，并汇总完成/剩余工时。
A3: MLE-1 | B3: 工程 | C3: M1 订单生成逻辑 | D3: 46153 | E3: 46171 | F3: in-progress | G3: 0 | I3: P0 | J3: demand_planning_refactor 已实现，待主入口切换、回归和性能确认
A4: MLE-2 | B4: 工程 | C4: M4 多产线排程 | D4: 46174 | E4: 46202 | F4: pending | G4: 0 | I4: P0 | J4: 多产线 case 通过，输出兼容
A5: MLE-3 | B5: 工程 | C5: filtered dataframe 优化 | D5: 46204 | E5: 46210 | F5: pending | G5: 0 | I5: MLE-1/MLE-2 | J5: 无 chained indexing 风险
A6: VAL-1 | B6: 校验 | C6: 输入数据校验 | D6: 46204 | E6: 46210 | F6: pending | G6: 0 | I6: P0 | J6: bad data 可被准确拦截
A7: MLE-4 | B7: 工程 | C7: 避免逐日 append | D7: 46219 | E7: 46225 | F7: pending | G7: 0 | I7: MLE-3 | J7: 高频 append 清零或可解释
A8: VAL-2 | B8: 校验 | C8: 中间数据校验 | D8: 46219 | E8: 46225 | F8: pending | G8: 0 | I8: VAL-1 | J8: 每日中间表校验报告
A9: TEST-1 | B9: 测试 | C9: E2E 网络构建 | D9: 46237 | E9: 46248 | F9: pending | G9: 0 | I9: MLE/VAL | J9: 30 天 E2E 成功跑通
A10: DOC-2 | B10: 文档 | C10: 历史回测文档 | D10: 46251 | E10: 46262 | F10: pending | G10: 0 | I10: TEST-1 | J10: simulated vs actual KPI 报告
A11: DOC-3 | B11: 文档 | C11: trade-off 分析 | D11: 46265 | E11: 46276 | F11: pending | G11: 0 | I11: TEST-1 | J11: cost/cash/service 报告
A12: DOC-4 | B12: 文档 | C12: PG 数据分布 | D12: 46279 | E12: 46293 | F12: pending | G12: 0 | I12: P0 | J12: PG 数据分布报告
A13: DOC-1 | B13: 文档 | C13: scope/problem/success criteria | D13: 46303 | E13: 46311 | F13: pending | G13: 0 | I13: 所有阶段 | J13: 最终范围与成功标准
A14: FINAL | B14: 收尾 | C14: 最终验收 | D14: 46314 | E14: 46317 | F14: pending | G14: 0 | I14: 全部任务 | J14: sign-off 完成
A20: Legend | B20: Planned | C20: Progress | D20: Done | E20: Blocked | F20: Weekend | G20: 0→100%

Sheet Overview
A1: 阶段 | B1: 时间 | C1: 主题 | D1: 主要产出
A2: Phase 0 | B2: 5/6 - 5/9 | C2: 启动、基线、代码审计 | D2: 项目计划、性能基线、风险清单
A3: Phase 1 | B3: 5/11 - 5/29 | C3: M1 订单生成逻辑升级 | D3: demand_planning_refactor 周→日订单生成、主入口切换评估、向量化回归报告
A4: Phase 2 | B4: 6/1 - 6/29 | C4: M4 多产线生产排程 | D4: 多产线排程逻辑、测试案例、性能报告
A5: Phase 3 | B5: 7/1 - 7/22 | C5: DataFrame 性能优化 + Validation | D5: filtered df 修复、append-free、输入/中间校验
A6: Phase 4 | B6: 8/3 - 8/14 | C6: E2E 测试网络 | D6: E2E 配置、30 天仿真、自动化脚本
A7: Phase 5 | B7: 8/17 - 9/28 | C7: 分析类文档 | D7: 回测、trade-off、PG 分布报告
A8: Phase 6 | B8: 10/8 - 10/22 | C8: 项目定义、收尾、验收 | D8: scope/problem/success criteria、最终交付包

Sheet WBS
A1: ID | B1: 工作流 | C1: 任务 | D1: 子任务 | E1: 交付物 | F1: 初始状态
A2: P0 | B2: 启动 | C2: 项目启动与基线 | D2: 计划确认、性能基线、风险审计 | E2: 项目计划、baseline、风险清单 | F2: pending
A3: MLE-1 | B3: Model Logic | C3: M1 订单生成逻辑 | D3: demand_planning_refactor 已落地周度订单、日度拆分、AO/normal、向量化；待主入口切换和回归 | E3: M1 重构代码、流程图、回归报告 | F3: in-progress
A4: MLE-2 | B4: Model Logic | C4: M4 多产线排程 | D4: SKU-line 候选、产能分配、换产、可靠性 | E4: M4 多产线逻辑 | F4: pending
A5: MLE-3 | B5: Model Logic | C5: filtered DataFrame 优化 | D5: chained indexing 审计、`.loc/.copy()` 规范 | E5: DataFrame 访问规范与修复 | F5: pending
A6: MLE-4 | B6: Model Logic | C6: 避免逐日 append | D6: list 累积、一次 concat、预分配 | E6: append-free 实现 | F6: pending
A7: VAL-1 | B7: Validation | C7: 用户输入校验 | D7: schema、必填、类型、范围、业务一致性 | E7: input validator | F7: pending
A8: VAL-2 | B8: Validation | C8: 中间数据校验 | D8: M1/M3/M4/M5 checkpoint、负数/重复/日期异常 | E8: intermediate validator | F8: pending
A9: TEST-1 | B9: Testing | C9: E2E 测试网络 | D9: mock network、smoke、30 天仿真、自动化 | E9: E2E 测试包 | F9: pending
A10: DOC-1 | B10: Documentation | C10: 项目范围与成功标准 | D10: scope、problem、success criteria、non-goals | E10: 项目定义文档 | F10: pending
A11: DOC-2 | B11: Documentation | C11: 历史回测文档 | D11: KPI 定义、simulated vs actual、偏差解释 | E11: 回测报告 | F11: pending
A12: DOC-3 | B12: Documentation | C12: Trade-off 分析 | D12: cost/cash/service KPI、场景、曲线 | E12: trade-off 报告 | F12: pending
... A16: CDP-3 | B16: Coding Design | C16: 死代码与注释块清理 | D16: 已完成 | E16: - | F16: done

Sheet Daily Plan
A1: 日期 | B1: 任务 ID | C1: 汇总到 | D1: 当日任务 | E1: 具体工作 | F1: 交付物 | G1: 状态 | H1: 计划工时 | I1: 已完成工时 | J1: 剩余工时 | K1: 工时进度 | L1: 备注
A2: 46148 | B2: P0 | C2: P0 | D2: 项目启动 | E2: 确认截图任务范围、冻结代码基线 | F2: 项目计划 v1 | G2: pending | H2: 10 | I2: 0 | J2: =MAX(H2-I2,0) | K2: =IF(H2=0,0,I2/H2)
A3: 46149 | B3: P0 | C3: P0 | D3: 性能基线 | E3: 跑现有 M1/M4/M5/M6 端到端流程，记录耗时 | F3: baseline 性能日志 | G3: pending | H3: 10 | I3: 0 | J3: =MAX(H3-I3,0) | K3: =IF(H3=0,0,I3/H3)
A4: 46150 | B4: P0 | C4: P0 | D4: 风险审计 | E4: 标记 M1/M4 高风险函数、长函数、逐日 append 点 | F4: 风险清单 | G4: pending | H4: 10 | I4: 0 | J4: =MAX(H4-I4,0) | K4: =IF(H4=0,0,I4/H4)
A5: 46153 | B5: MLE-1 | C5: MLE-1 | D5: M1 现状梳理 | E5: 以 src/modules/demand_planning_refactor 为准复核 forecast → weekly orders → daily orders → shipment | F5: M1 流程图 | G5: in-progress | H5: 10 | I5: 0 | J5: =MAX(H5-I5,0) | K5: =IF(H5=0,0,I5/H5) | L5: 重构代码已存在，文档按现状同步
A6: 46154 | B6: MLE-1 | C6: MLE-1 | D6: 周度订单设计 | E6: 复核 week first, then split to valid order dates 的数据结构 | F6: M1 设计说明 | G6: in-progress | H6: 10 | I6: 0 | J6: =MAX(H6-I6,0) | K6: =IF(H6=0,0,I6/H6) | L6: 已在 generate_weekly_orders() / split_weekly_orders_to_daily() 落地
A7: 46155 | B7: MLE-1 | C7: MLE-1 | D7: 日度拆分规则 | E7: 复核整数拆分、余数分配、OrderCalendar 有效下单日规则 | F7: 拆分规则表 | G7: in-progress | H7: 10 | I7: 0 | J7: =MAX(H7-I7,0) | K7: =IF(H7=0,0,I7/H7) | L7: OrderCalendar 只决定 order_date，不决定 require_date
A8: 46156 | B8: MLE-1 | C8: MLE-1 | D8: AO/Normal 适配 | E8: 复核 AO advance_days 最后作用、normal 当天下当天要 | F8: AO/Normal 规则说明 | G8: in-progress | H8: 10 | I8: 0 | J8: =MAX(H8-I8,0) | K8: =IF(H8=0,0,I8/H8) | L8: date=require_date, simulation_date=order_date
A9: 46157 | B9: MLE-1 | C9: MLE-1 | D9: 单元测试设计 | E9: 补齐 M1 周→日拆分和输出契约测试 | F9: M1 unit test case | G9: in-progress | H9: 10 | I9: 0 | J9: =MAX(H9-I9,0) | K9: =IF(H9=0,0,I9/H9) | L9: 已有 functional_tests/module_tests/feature_tests/integration_tests
A10: 46160 | B10: MLE-1 | C10: MLE-1 | D10: 实现周度订单生成 | E10: 回归 generate_weekly_orders() 总量、结构、CoV 和随机稳定性 | F10: M1 回归记录 | G10: pending | H10: 10 | I10: 0 | J10: =MAX(H10-I10,0) | K10: =IF(H10=0,0,I10/H10) | L10: 代码已在 refactor 模块，待回归确认
A11: 46161 | B11: MLE-1 | C11: MLE-1 | D11: 实现日度拆分 | E11: 回归 split_weekly_orders_to_daily() 数量守恒和下单日过滤 | F11: 日订单输出 | G11: pending | H11: 10 | I11: 0 | J11: =MAX(H11-I11,0) | K11: =IF(H11=0,0,I11/H11) | L11: 代码已在 refactor 模块，待回归确认
A12: 46162 | B12: MLE-1 | C12: MLE-1 | D12: 向量化处理 | E12: 回归 consume_orders()、_apply_orders_consumption() 优化路径 | F12: 向量化验证 | G12: pending | H12: 10 | I12: 0 | J12: =MAX(H12-I12,0) | K12: =IF(H12=0,0,I12/H12) | L12: 默认 DEFAULT_USE_OPTIMIZED_CONSUME=True
A13: 46163 | B13: MLE-1 | C13: MLE-1 | D13: 随机误差一致性 | E13: 确保 forecast_error 随机数序列不漂移 | F13: 随机一致性检查 | G13: pending | H13: 10 | I13: 0 | J13: =MAX(H13-I13,0) | K13: =IF(H13=0,0,I13/H13)
A14: 46164 | B14: MLE-1 | C14: MLE-1 | D14: M1 回归测试 | E14: 对比旧版 OrderLog / SupplyDemandLog | F14: M1 diff 报告 | G14: pending | H14: 10 | I14: 0 | J14: =MAX(H14-I14,0) | K14: =IF(H14=0,0,I14/H14)
A15: 46167 | B15: MLE-1 | C15: MLE-1 | D15: 性能优化 | E15: 缓存周→日 forecast，避免每天重复展开 | F15: M1 cache 实现 | G15: pending | H15: 10 | I15: 0 | J15: =MAX(H15-I15,0) | K15: =IF(H15=0,0,I15/H15)
A16: 46168 | B16: MLE-1 | C16: MLE-1 | D16: 下游兼容 | E16: 验证 M3/M5 读取 M1 输出不受影响 | F16: 兼容性报告 | G16: pending | H16: 10 | I16: 0 | J16: =MAX(H16-I16,0) | K16: =IF(H16=0,0,I16/H16)
A17: 46169 | B17: CDP-1 | C17: CDP-1 | D17: 函数拆分 | E17: 拆分 M1 中长函数，保留行为一致 | F17: 小函数化 PR | G17: pending | H17: 10 | I17: 0 | J17: =MAX(H17-I17,0) | K17: =IF(H17=0,0,I17/H17)
A18: 46170 | B18: MLE-1 | C18: MLE-1 | D18: 性能 benchmark | E18: 记录优化前后 M1 每日平均耗时 | F18: M1 性能报告 | G18: pending | H18: 10 | I18: 0 | J18: =MAX(H18-I18,0) | K18: =IF(H18=0,0,I18/H18)
A19: 46171 | B19: MLE-1 | C19: MLE-1 | D19: Phase 1 验收 | E19: 代码审查、结果确认、风险关闭 | F19: M1 验收记录 | G19: pending | H19: 10 | I19: 0 | J19: =MAX(H19-I19,0) | K19: =IF(H19=0,0,I19/H19)
A20: 46174 | B20: MLE-2 | C20: MLE-2 | D20: M4 现状梳理 | E20: 梳理 SKU→line、capacity、changeover 数据流 | F20: M4 流程图 | G20: pending | H20: 10 | I20: 0 | J20: =MAX(H20-I20,0) | K20: =IF(H20=0,0,I20/H20)
A21: 46175 | B21: MLE-2 | C21: MLE-2 | D21: 多产线需求定义 | E21: 明确一个 SKU 可映射多条产线的业务规则 | F21: 规则说明 | G21: pending | H21: 10 | I21: 0 | J21: =MAX(H21-I21,0) | K21: =IF(H21=0,0,I21/H21)
A22: 46176 | B22: MLE-2 | C22: MLE-2 | D22: 数据模型设计 | E22: 设计 SKU-line candidate table、priority、rate | F22: 数据结构草案 | G22: pending | H22: 10 | I22: 0 | J22: =MAX(H22-I22,0) | K22: =IF(H22=0,0,I22/H22)
A23: 46177 | B23: MLE-2 | C23: MLE-2 | D23: 约束识别 | E23: 识别 capacity、changeover、reliability、available_date 约束 | F23: 约束清单 | G23: pending | H23: 10 | I23: 0 | J23: =MAX(H23-I23,0) | K23: =IF(H23=0,0,I23/H23)
A24: 46178 | B24: MLE-2 | C24: MLE-2 | D24: 测试场景设计 | E24: 设计单 SKU 多线、产能不足、换产冲突用例 | F24: M4 test cases | G24: pending | H24: 10 | I24: 0 | J24: =MAX(H24-I24,0) | K24: =IF(H24=0,0,I24/H24)
... A59: 46227 | B59: MLE/VAL | C59: VAL-2 | D59: 7 月验收 | E59: 汇总 DataFrame 优化与 validation 结果 | F59: 7 月验收记录 | G59: pending | H59: 10 | I59: 0 | J59: =MAX(H59-I59,0) | K59: =IF(H59=0,0,I59/H59)
A60: 46237 | B60: TEST-1 | C60: TEST-1 | D60: E2E 网络扩展 | E60: 增加多 SKU、多地点、多产线场景 | F60: extended network | G60: pending | H60: 10 | I60: 0 | J60: =MAX(H65-I65,0) | K60: =IF(H65=0,0,I65/H65)
A61: 46238 | B61: TEST-1 | C61: TEST-1 | D61: M1/M3 验证 | E61: 检查订单、供需日志、净需求流转 | F61: M1/M3 report | G61: pending | H61: 10 | I61: 0 | J61: =MAX(H66-I66,0) | K61: =IF(H66=0,0,I66/H66)
A62: 46239 | B62: TEST-1 | C62: TEST-1 | D62: M4/M5 验证 | E62: 检查生产计划、调拨计划 | F62: M4/M5 report | G62: pending | H62: 10 | I62: 0 | J62: =MAX(H67-I67,0) | K62: =IF(H67=0,0,I67/H67)
A63: 46240 | B63: TEST-1 | C63: TEST-1 | D63: M6/库存验证 | E63: 检查物流、GR、库存平衡 | F63: M6/inventory report | G63: pending | H63: 10 | I63: 0 | J63: =MAX(H68-I68,0) | K63: =IF(H68=0,0,I68/H68)
A64: 46241 | B64: TEST-1 | C64: TEST-1 | D64: E2E 修复 | E64: 修复端到端差异 | F64: 修复记录 | G64: pending | H64: 10 | I64: 0 | J64: =MAX(H69-I69,0) | K64: =IF(H69=0,0,I69/H69)
A65: 46244 | B65: TEST-1 | C65: TEST-1 | D65: 30 天测试 | E65: 跑 30 天 E2E | F65: 30-day output | G65: pending | H65: 10 | I65: 0 | J65: =MAX(H70-I70,0) | K65: =IF(H70=0,0,I70/H70)
A66: 46245 | B66: TEST-1 | C66: TEST-1 | D66: 结果分析 | E66: 检查库存、service、cuts、deployments | F66: E2E analysis | G66: pending | H66: 10 | I66: 0 | J66: =MAX(H71-I71,0) | K66: =IF(H71=0,0,I71/H71)
A67: 46246 | B67: TEST-1 | C67: TEST-1 | D67: 自动化脚本 | E67: 固化 E2E run + compare 脚本 | F67: e2e script | G67: pending | H67: 10 | I67: 0 | J67: =MAX(H72-I72,0) | K67: =IF(H72=0,0,I72/H72)
A68: 46247 | B68: TEST-1 | C68: TEST-1 | D68: 报告整理 | E68: 输出 E2E 测试报告 | F68: E2E report | G68: pending | H68: 10 | I68: 0 | J68: =MAX(H73-I73,0) | K68: =IF(H73=0,0,I73/H73)
A69: 46248 | B69: TEST-1 | C69: TEST-1 | D69: E2E 验收 | E69: E2E 网络冻结 | F69: E2E 验收记录 | G69: pending | H69: 10 | I69: 0 | J69: =MAX(H74-I74,0) | K69: =IF(H74=0,0,I74/H74)
A70: 46251 | B70: DOC-2 | C70: DOC-2 | D70: 回测资料整理 | E70: 整理 baby case 已完成回测结果 | F70: 回测资料包 | G70: pending | H70: 10 | I70: 0 | J70: =MAX(H75-I75,0) | K70: =IF(H75=0,0,I75/H75)
A71: 46252 | B71: DOC-2 | C71: DOC-2 | D71: KPI 定义 | E71: 明确 simulated vs actual KPI 列表 | F71: KPI 字典 | G71: pending | H71: 10 | I71: 0 | J71: =MAX(H76-I76,0) | K71: =IF(H76=0,0,I76/H76)
... A102: 46307 | B102: DOC-1 | C102: DOC-1 | D102: 成功标准 | E102: 定义性能、准确性、可维护性、验证标准 | F102: success criteria | G102: pending | H102: 10 | I102: 0 | J102: =MAX(H107-I107,0) | K102: =IF(H107=0,0,I107/H107)
A103: 46308 | B103: DOC-1 | C103: DOC-1 | D103: 文档缓冲 | E103: 检查范围与交付物一致性 | F103: checklist | G103: pending | H103: 10 | I103: 0 | J103: =MAX(H111-I111,0) | K103: =IF(H111=0,0,I111/H111)
A104: 46309 | B104: DOC-1 | C104: DOC-1 | D104: 文档缓冲 | E104: 准备评审版本 | F104: review version | G104: pending | H104: 10 | I104: 0 | J104: =MAX(H112-I112,0) | K104: =IF(H112=0,0,I112/H112)
...

Sheet Progress Tracker
A1: ID | B1: 工作流 | C1: 任务 | D1: 计划开始 | E1: 计划结束 | F1: 工期 | G1: 计划工时 | H1: 已完成工时 | I1: 剩余工时 | J1: 工时进度 | K1: 当前状态 | L1: 依赖 | M1: 验收标准 | N1: 排期说明
A2: P0 | B2: 启动 | C2: 基线、风险、计划 | D2: 46148 | E2: 46150 | F2: 3d | G2: =SUMIF('Daily Plan'!$C:$C,A2,'Daily Plan'!$H:$H) | H2: =SUMIF('Daily Plan'!$C:$C,A2,'Daily Plan'!$I:$I) | I2: =MAX(G2-H2,0) | J2: =IF(G2=0,IF(K2="done",1,0),H2/G2) | K2: pending | L2: 无 | M2: baseline + risk list 完成
A3: MLE-1 | B3: 工程 | C3: M1 订单生成逻辑 | D3: 46153 | E3: 46171 | F3: 14d | G3: =SUMIF('Daily Plan'!$C:$C,A3,'Daily Plan'!$H:$H) | H3: =SUMIF('Daily Plan'!$C:$C,A3,'Daily Plan'!$I:$I) | I3: =MAX(G3-H3,0) | J3: =IF(G3=0,IF(K3="done",1,0),H3/G3) | K3: in-progress | L3: P0 | M3: demand_planning_refactor 已实现；待主入口切换、OrderLog/SupplyDemandLog 回归和性能确认 | N3: 2026-05-08 按重构代码同步计划，后续以回归和集成切换为主
A4: MLE-2 | B4: 工程 | C4: M4 多产线排程 | D4: 46174 | E4: 46199 | F4: 19d | G4: =SUMIF('Daily Plan'!$C:$C,A4,'Daily Plan'!$H:$H) | H4: =SUMIF('Daily Plan'!$C:$C,A4,'Daily Plan'!$I:$I) | I4: =MAX(G4-H4,0) | J4: =IF(G4=0,IF(K4="done",1,0),H4/G4) | K4: pending | L4: P0 | M4: 多产线 case 通过，输出兼容
A5: CDP-1 | B5: 代码设计 | C5: 1000+ 行函数拆分 | D5: 46169 | E5: 46190 | F5: 2d | G5: =SUMIF('Daily Plan'!$C:$C,A5,'Daily Plan'!$H:$H) | H5: =SUMIF('Daily Plan'!$C:$C,A5,'Daily Plan'!$I:$I) | I5: =MAX(G5-H5,0) | J5: =IF(G5=0,IF(K5="done",1,0),H5/G5) | K5: pending | L5: MLE-1/MLE-2 | M5: 长函数拆分 PR 完成且测试保护通过 | N5: 离散排期：5/27, 6/17
A6: MLE-3 | B6: 工程 | C6: filtered dataframe 优化 | D6: 46202 | E6: 46206 | F6: 5d | G6: =SUMIF('Daily Plan'!$C:$C,A6,'Daily Plan'!$H:$H) | H6: =SUMIF('Daily Plan'!$C:$C,A6,'Daily Plan'!$I:$I) | I6: =MAX(G6-H6,0) | J6: =IF(G6=0,IF(K6="done",1,0),H6/G6) | K6: pending | L6: MLE-1/MLE-2 | M6: 无 chained indexing 风险
A7: VAL-1 | B7: 校验 | C7: 输入数据校验 | D7: 46209 | E7: 46213 | F7: 5d | G7: =SUMIF('Daily Plan'!$C:$C,A7,'Daily Plan'!$H:$H) | H7: =SUMIF('Daily Plan'!$C:$C,A7,'Daily Plan'!$I:$I) | I7: =MAX(G7-H7,0) | J7: =IF(G7=0,IF(K7="done",1,0),H7/G7) | K7: pending | L7: P0 | M7: bad data 可被准确拦截
A8: MLE-4 | B8: 工程 | C8: 避免逐日 append | D8: 46216 | E8: 46220 | F8: 5d | G8: =SUMIF('Daily Plan'!$C:$C,A8,'Daily Plan'!$H:$H) | H8: =SUMIF('Daily Plan'!$C:$C,A8,'Daily Plan'!$I:$I) | I8: =MAX(G8-H8,0) | J8: =IF(G8=0,IF(K8="done",1,0),H8/G8) | K8: pending | L8: MLE-3 | M8: 高频 append 清零或可解释
A9: VAL-2 | B9: 校验 | C9: 中间数据校验 | D9: 46223 | E9: 46227 | F9: 5d | G9: =SUMIF('Daily Plan'!$C:$C,A9,'Daily Plan'!$H:$H) | H9: =SUMIF('Daily Plan'!$C:$C,A9,'Daily Plan'!$I:$I) | I9: =MAX(G9-H9,0) | J9: =IF(G9=0,IF(K9="done",1,0),H9/G9) | K9: pending | L9: VAL-1 | M9: 每日中间表校验报告
A10: TEST-1 | B10: 测试 | C10: E2E 网络构建 | D10: 46230 | E10: 46248 | F10: 15d | G10: =SUMIF('Daily Plan'!$C:$C,A10,'Daily Plan'!$H:$H) | H10: =SUMIF('Daily Plan'!$C:$C,A10,'Daily Plan'!$I:$I) | I10: =MAX(G10-H10,0) | J10: =IF(G10=0,IF(K10="done",1,0),H10/G10) | K10: pending | L10: MLE/VAL | M10: 30 天 E2E 成功跑通
A11: DOC-2 | B11: 文档 | C11: 历史回测文档 | D11: 46251 | E11: 46262 | F11: 10d | G11: =SUMIF('Daily Plan'!$C:$C,A11,'Daily Plan'!$H:$H) | H11: =SUMIF('Daily Plan'!$C:$C,A11,'Daily Plan'!$I:$I) | I11: =MAX(G11-H11,0) | J11: =IF(G11=0,IF(K11="done",1,0),H11/G11) | K11: pending | L11: TEST-1 | M11: simulated vs actual KPI 报告
A12: DOC-3 | B12: 文档 | C12: trade-off 分析 | D12: 46265 | E12: 46276 | F12: 10d | G12: =SUMIF('Daily Plan'!$C:$C,A12,'Daily Plan'!$H:$H) | H12: =SUMIF('Daily Plan'!$C:$C,A12,'Daily Plan'!$I:$I) | I12: =MAX(G12-H12,0) | J12: =IF(G12=0,IF(K12="done",1,0),H12/G12) | K12: pending | L12: TEST-1 | M12: cost/cash/service 报告
A13: DOC-4 | B13: 文档 | C13: PG 数据分布 | D13: 46279 | E13: 46290 | F13: 10d | G13: =SUMIF('Daily Plan'!$C:$C,A13,'Daily Plan'!$H:$H) | H13: =SUMIF('Daily Plan'!$C:$C,A13,'Daily Plan'!$I:$I) | I13: =MAX(G13-H13,0) | J13: =IF(G13=0,IF(K13="done",1,0),H13/G13) | K13: pending | L13: P0 | M13: PG 数据分布报告
A14: DOC-1 | B14: 文档 | C14: scope/problem/success criteria | D14: 46293 | E14: 46304 | F14: 10d | G14: =SUMIF('Daily Plan'!$C:$C,A14,'Daily Plan'!$H:$H) | H14: =SUMIF('Daily Plan'!$C:$C,A14,'Daily Plan'!$I:$I) | I14: =MAX(G14-H14,0) | J14: =IF(G14=0,IF(K14="done",1,0),H14/G14) | K14: pending | L14: 所有阶段 | M14: 最终范围与成功标准
A15: CDP-2 | B15: 代码设计 | C15: 硬编码参数清理 | F15: 0d | G15: =SUMIF('Daily Plan'!$C:$C,A15,'Daily Plan'!$H:$H) | H15: =SUMIF('Daily Plan'!$C:$C,A15,'Daily Plan'!$I:$I) | I15: =MAX(G15-H15,0) | J15: =IF(G15=0,IF(K15="done",1,0),H15/G15) | K15: done | L15: 无 | M15: 已完成，无新增计划工时
A16: CDP-3 | B16: 代码设计 | C16: 死代码与注释块清理 | F16: 0d | G16: =SUMIF('Daily Plan'!$C:$C,A16,'Daily Plan'!$H:$H) | H16: =SUMIF('Daily Plan'!$C:$C,A16,'Daily Plan'!$I:$I) | I16: =MAX(G16-H16,0) | J16: =IF(G16=0,IF(K16="done",1,0),H16/G16) | K16: done | L16: 无 | M16: 已完成，无新增计划工时
A17: FINAL | B17: 收尾 | C17: 最终验收 | D17: 46307 | E17: 46310 | F17: 4d | G17: =SUMIF('Daily Plan'!$C:$C,A17,'Daily Plan'!$H:$H) | H17: =SUMIF('Daily Plan'!$C:$C,A17,'Daily Plan'!$I:$I) | I17: =MAX(G17-H17,0) | J17: =IF(G17=0,IF(K17="done",1,0),H17/G17) | K17: pending | L17: 全部任务 | M17: sign-off 完成

Sheet Hourly Gantt
A1: ID | B1: 工作流 | C1: 任务 | D1: 计划开始 | E1: 计划结束 | F1: 状态 | G1: 计划工时 | H1: 已完成工时 | I1: 剩余工时 | J1: 工时进度 | K1: 依赖 | L1: 验收标准 | M1: 46148 | N1: 46149 | O1: 46150 | P1: 46151 | Q1: 46152 | R1: 46153 | S1: 46154 | T1: 46155 | U1: 46156 | V1: 46157 | W1: 46158 | X1: 46159 | Y1: 46160 | Z1: 46161 | AA1: 46162 | AB1: 46163 | AC1: 46164 | AD1: 46165 | AE1: 46166 | AF1: 46167 | AG1: 46168 | AH1: 46169 | AI1: 46170 | AJ1: 46171 | AK1: 46172 | AL1: 46173 | AM1: 46174 | AN1: 46175 | AO1: 46176 | AP1: 46177 | AQ1: 46178 | AR1: 46179 | AS1: 46180 | AT1: 46181 | AU1: 46182 | AV1: 46183 | AW1: 46184 | AX1: 46185 | AY1: 46186 | AZ1: 46187 | BA1: 46188 | BB1: 46189 | BC1: 46190 | BD1: 46191 | BE1: 46192 | BF1: 46193 | BG1: 46194 | BH1: 46195 | BI1: 46196 | BJ1: 46197 | BK1: 46198 | BL1: 46199 | BM1: 46200 | BN1: 46201 | BO1: 46202 | BP1: 46203 | BQ1: 46204 | BR1: 46205 | BS1: 46206 | BT1: 46207 | BU1: 46208 | BV1: 46209 | BW1: 46210 | BX1: 46211 | BY1: 46212 | BZ1: 46213 | CA1: 46214 | CB1: 46215 | CC1: 46216 | CD1: 46217 | CE1: 46218 | CF1: 46219 | CG1: 46220 | CH1: 46221 | CI1: 46222 | CJ1: 46223 | CK1: 46224 | CL1: 46225 | CM1: 46226 | CN1: 46227 | CO1: 46228 | CP1: 46229 | CQ1: 46230 | CR1: 46231 | CS1: 46232 | CT1: 46233 | CU1: 46234 | CV1: 46235 | CW1: 46236 | CX1: 46237 | CY1: 46238 | CZ1: 46239 | DA1: 46240 | DB1: 46241 | DC1: 46242 | DD1: 46243 | DE1: 46244 | DF1: 46245 | DG1: 46246 | DH1: 46247 | DI1: 46248 | DJ1: 46249 | DK1: 46250 | DL1: 46251 | DM1: 46252 | DN1: 46253 | DO1: 46254 | DP1: 46255 | DQ1: 46256 | DR1: 46257 | DS1: 46258 | DT1: 46259 | DU1: 46260 | DV1: 46261 | DW1: 46262 | DX1: 46263 | DY1: 46264 | DZ1: 46265 | EA1: 46266 | EB1: 46267 | EC1: 46268 | ED1: 46269 | EE1: 46270 | EF1: 46271 | EG1: 46272 | EH1: 46273 | EI1: 46274 | EJ1: 46275 | EK1: 46276 | EL1: 46277 | EM1: 46278 | EN1: 46279 | EO1: 46280 | EP1: 46281 | EQ1: 46282 | ER1: 46283 | ES1: 46284 | ET1: 46285 | EU1: 46286 | EV1: 46287 | EW1: 46288 | EX1: 46289 | EY1: 46290 | EZ1: 46291 | FA1: 46292 | FB1: 46293 | FC1: 46294 | FD1: 46295 | FE1: 46296 | FF1: 46297 | FG1: 46298 | FH1: 46299 | FI1: 46300 | FJ1: 46301 | FK1: 46302 | FL1: 46303 | FM1: 46304 | FN1: 46305 | FO1: 46306 | FP1: 46307 | FQ1: 46308 | FR1: 46309 | FS1: 46310
A2: P0 | B2: 启动 | C2: 基线、风险、计划 | D2: 46148 | E2: 46150 | F2: pending | G2: =SUMIF('Daily Plan'!$C:$C,A2,'Daily Plan'!$H:$H) | H2: =SUMIF('Daily Plan'!$C:$C,A2,'Daily Plan'!$I:$I) | I2: =MAX(G2-H2,0) | J2: =IF(G2=0,IF(F2="done",1,0),H2/G2) | K2: 无 | L2: baseline + risk list 完成 | M2: =SUMIFS('Daily Plan'!$H:$H,'Daily Plan'!$C:$C,$A2,'Daily Plan'!$A:$A,M$1) | N2: =SUMIFS('Daily Plan'!$H:$H,'Daily Plan'!$C:$C,$A2,'Daily Plan'!$A:$A,N$1) | O2: =SUMIFS('Daily Plan'!$H:$H,'Daily Plan'!$C:$C,$A2,'Daily Plan'!$A:$A,O$1) | P2: =SUMIFS('Daily Plan'!$H:$H,'Daily Plan'!$C:$C,$A2,'Daily Plan'!$A:$A,P$1) | Q2: =SUMIFS('Daily Plan'!$H:$H,'Daily Plan'!$C:$C,$A2,'Daily Plan'!$A:$A,Q$1) | R2: =SUMIFS('Daily Plan'!$H:$H,'Daily Plan'!$C:$C,$A2,'Daily Plan'!$A:$A,R$1) | S2: =SUMIFS('Daily Plan'!$H:$H,'Daily Plan'!$C:$C,$A2,'Daily Plan'!$A:$A,S$1) | T2: =SUMIFS('Daily Plan'!$H:$H,'Daily Plan'!$C:$C,$A2,'Daily Plan'!$A:$A,T$1) | ... FS2: =SUMIFS('Daily Plan'!$H:$H,'Daily Plan'!$C:$C,$A2,'Daily Plan'!$A:$A,FS$1)
A3: MLE-1 | B3: 工程 | C3: M1 订单生成逻辑 | D3: 46153 | E3: 46171 | F3: pending | G3: =SUMIF('Daily Plan'!$C:$C,A3,'Daily Plan'!$H:$H) | H3: =SUMIF('Daily Plan'!$C:$C,A3,'Daily Plan'!$I:$I) | I3: =MAX(G3-H3,0) | J3: =IF(G3=0,IF(F3="done",1,0),H3/G3) | K3: P0 | L3: OrderLog/SupplyDemandLog 回归一致，性能提升 | M3: =SUMIFS('Daily Plan'!$H:$H,'Daily Plan'!$C:$C,$A3,'Daily Plan'!$A:$A,M$1) | N3: =SUMIFS('Daily Plan'!$H:$H,'Daily Plan'!$C:$C,$A3,'Daily Plan'!$A:$A,N$1) | O3: =SUMIFS('Daily Plan'!$H:$H,'Daily Plan'!$C:$C,$A3,'Daily Plan'!$A:$A,O$1) | P3: =SUMIFS('Daily Plan'!$H:$H,'Daily Plan'!$C:$C,$A3,'Daily Plan'!$A:$A,P$1) | Q3: =SUMIFS('Daily Plan'!$H:$H,'Daily Plan'!$C:$C,$A3,'Daily Plan'!$A:$A,Q$1) | R3: =SUMIFS('Daily Plan'!$H:$H,'Daily Plan'!$C:$C,$A3,'Daily Plan'!$A:$A,R$1) | S3: =SUMIFS('Daily Plan'!$H:$H,'Daily Plan'!$C:$C,$A3,'Daily Plan'!$A:$A,S$1) | T3: =SUMIFS('Daily Plan'!$H:$H,'Daily Plan'!$C:$C,$A3,'Daily Plan'!$A:$A,T$1) | ... FS3: =SUMIFS('Daily Plan'!$H:$H,'Daily Plan'!$C:$C,$A3,'Daily Plan'!$A:$A,FS$1)
A4: MLE-2 | B4: 工程 | C4: M4 多产线排程 | D4: 46174 | E4: 46199 | F4: pending | G4: =SUMIF('Daily Plan'!$C:$C,A4,'Daily Plan'!$H:$H) | H4: =SUMIF('Daily Plan'!$C:$C,A4,'Daily Plan'!$I:$I) | I4: =MAX(G4-H4,0) | J4: =IF(G4=0,IF(F4="done",1,0),H4/G4) | K4: P0 | L4: 多产线 case 通过，输出兼容 | M4: =SUMIFS('Daily Plan'!$H:$H,'Daily Plan'!$C:$C,$A4,'Daily Plan'!$A:$A,M$1) | N4: =SUMIFS('Daily Plan'!$H:$H,'Daily Plan'!$C:$C,$A4,'Daily Plan'!$A:$A,N$1) | O4: =SUMIFS('Daily Plan'!$H:$H,'Daily Plan'!$C:$C,$A4,'Daily Plan'!$A:$A,O$1) | P4: =SUMIFS('Daily Plan'!$H:$H,'Daily Plan'!$C:$C,$A4,'Daily Plan'!$A:$A,P$1) | Q4: =SUMIFS('Daily Plan'!$H:$H,'Daily Plan'!$C:$C,$A4,'Daily Plan'!$A:$A,Q$1) | R4: =SUMIFS('Daily Plan'!$H:$H,'Daily Plan'!$C:$C,$A4,'Daily Plan'!$A:$A,R$1) | S4: =SUMIFS('Daily Plan'!$H:$H,'Daily Plan'!$C:$C,$A4,'Daily Plan'!$A:$A,S$1) | T4: =SUMIFS('Daily Plan'!$H:$H,'Daily Plan'!$C:$C,$A4,'Daily Plan'!$A:$A,T$1) | ... FS4: =SUMIFS('Daily Plan'!$H:$H,'Daily Plan'!$C:$C,$A4,'Daily Plan'!$A:$A,FS$1)
A5: CDP-1 | B5: 代码设计 | C5: 1000+ 行函数拆分 | D5: 46169 | E5: 46190 | F5: pending | G5: =SUMIF('Daily Plan'!$C:$C,A5,'Daily Plan'!$H:$H) | H5: =SUMIF('Daily Plan'!$C:$C,A5,'Daily Plan'!$I:$I) | I5: =MAX(G5-H5,0) | J5: =IF(G5=0,IF(F5="done",1,0),H5/G5) | K5: MLE-1/MLE-2 | L5: 长函数拆分 PR 完成且测试保护通过 | M5: =SUMIFS('Daily Plan'!$H:$H,'Daily Plan'!$C:$C,$A5,'Daily Plan'!$A:$A,M$1) | N5: =SUMIFS('Daily Plan'!$H:$H,'Daily Plan'!$C:$C,$A5,'Daily Plan'!$A:$A,N$1) | O5: =SUMIFS('Daily Plan'!$H:$H,'Daily Plan'!$C:$C,$A5,'Daily Plan'!$A:$A,O$1) | P5: =SUMIFS('Daily Plan'!$H:$H,'Daily Plan'!$C:$C,$A5,'Daily Plan'!$A:$A,P$1) | Q5: =SUMIFS('Daily Plan'!$H:$H,'Daily Plan'!$C:$C,$A5,'Daily Plan'!$A:$A,Q$1) | R5: =SUMIFS('Daily Plan'!$H:$H,'Daily Plan'!$C:$C,$A5,'Daily Plan'!$A:$A,R$1) | S5: =SUMIFS('Daily Plan'!$H:$H,'Daily Plan'!$C:$C,$A5,'Daily Plan'!$A:$A,S$1) | T5: =SUMIFS('Daily Plan'!$H:$H,'Daily Plan'!$C:$C,$A5,'Daily Plan'!$A:$A,T$1) | ... FS5: =SUMIFS('Daily Plan'!$H:$H,'Daily Plan'!$C:$C,$A5,'Daily Plan'!$A:$A,FS$1)
A6: MLE-3 | B6: 工程 | C6: filtered dataframe 优化 | D6: 46202 | E6: 46206 | F6: pending | G6: =SUMIF('Daily Plan'!$C:$C,A6,'Daily Plan'!$H:$H) | H6: =SUMIF('Daily Plan'!$C:$C,A6,'Daily Plan'!$I:$I) | I6: =MAX(G6-H6,0) | J6: =IF(G6=0,IF(F6="done",1,0),H6/G6) | K6: MLE-1/MLE-2 | L6: 无 chained indexing 风险 | M6: =SUMIFS('Daily Plan'!$H:$H,'Daily Plan'!$C:$C,$A6,'Daily Plan'!$A:$A,M$1) | N6: =SUMIFS('Daily Plan'!$H:$H,'Daily Plan'!$C:$C,$A6,'Daily Plan'!$A:$A,N$1) | O6: =SUMIFS('Daily Plan'!$H:$H,'Daily Plan'!$C:$C,$A6,'Daily Plan'!$A:$A,O$1) | P6: =SUMIFS('Daily Plan'!$H:$H,'Daily Plan'!$C:$C,$A6,'Daily Plan'!$A:$A,P$1) | Q6: =SUMIFS('Daily Plan'!$H:$H,'Daily Plan'!$C:$C,$A6,'Daily Plan'!$A:$A,Q$1) | R6: =SUMIFS('Daily Plan'!$H:$H,'Daily Plan'!$C:$C,$A6,'Daily Plan'!$A:$A,R$1) | S6: =SUMIFS('Daily Plan'!$H:$H,'Daily Plan'!$C:$C,$A6,'Daily Plan'!$A:$A,S$1) | T6: =SUMIFS('Daily Plan'!$H:$H,'Daily Plan'!$C:$C,$A6,'Daily Plan'!$A:$A,T$1) | ... FS6: =SUMIFS('Daily Plan'!$H:$H,'Daily Plan'!$C:$C,$A6,'Daily Plan'!$A:$A,FS$1)
A7: VAL-1 | B7: 校验 | C7: 输入数据校验 | D7: 46209 | E7: 46213 | F7: pending | G7: =SUMIF('Daily Plan'!$C:$C,A7,'Daily Plan'!$H:$H) | H7: =SUMIF('Daily Plan'!$C:$C,A7,'Daily Plan'!$I:$I) | I7: =MAX(G7-H7,0) | J7: =IF(G7=0,IF(F7="done",1,0),H7/G7) | K7: P0 | L7: bad data 可被准确拦截 | M7: =SUMIFS('Daily Plan'!$H:$H,'Daily Plan'!$C:$C,$A7,'Daily Plan'!$A:$A,M$1) | N7: =SUMIFS('Daily Plan'!$H:$H,'Daily Plan'!$C:$C,$A7,'Daily Plan'!$A:$A,N$1) | O7: =SUMIFS('Daily Plan'!$H:$H,'Daily Plan'!$C:$C,$A7,'Daily Plan'!$A:$A,O$1) | P7: =SUMIFS('Daily Plan'!$H:$H,'Daily Plan'!$C:$C,$A7,'Daily Plan'!$A:$A,P$1) | Q7: =SUMIFS('Daily Plan'!$H:$H,'Daily Plan'!$C:$C,$A7,'Daily Plan'!$A:$A,Q$1) | R7: =SUMIFS('Daily Plan'!$H:$H,'Daily Plan'!$C:$C,$A7,'Daily Plan'!$A:$A,R$1) | S7: =SUMIFS('Daily Plan'!$H:$H,'Daily Plan'!$C:$C,$A7,'Daily Plan'!$A:$A,S$1) | T7: =SUMIFS('Daily Plan'!$H:$H,'Daily Plan'!$C:$C,$A7,'Daily Plan'!$A:$A,T$1) | ... FS7: =SUMIFS('Daily Plan'!$H:$H,'Daily Plan'!$C:$C,$A7,'Daily Plan'!$A:$A,FS$1)
A8: MLE-4 | B8: 工程 | C8: 避免逐日 append | D8: 46216 | E8: 46220 | F8: pending | G8: =SUMIF('Daily Plan'!$C:$C,A8,'Daily Plan'!$H:$H) | H8: =SUMIF('Daily Plan'!$C:$C,A8,'Daily Plan'!$I:$I) | I8: =MAX(G8-H8,0) | J8: =IF(G8=0,IF(F8="done",1,0),H8/G8) | K8: MLE-3 | L8: 高频 append 清零或可解释 | M8: =SUMIFS('Daily Plan'!$H:$H,'Daily Plan'!$C:$C,$A8,'Daily Plan'!$A:$A,M$1) | N8: =SUMIFS('Daily Plan'!$H:$H,'Daily Plan'!$C:$C,$A8,'Daily Plan'!$A:$A,N$1) | O8: =SUMIFS('Daily Plan'!$H:$H,'Daily Plan'!$C:$C,$A8,'Daily Plan'!$A:$A,O$1) | P8: =SUMIFS('Daily Plan'!$H:$H,'Daily Plan'!$C:$C,$A8,'Daily Plan'!$A:$A,P$1) | Q8: =SUMIFS('Daily Plan'!$H:$H,'Daily Plan'!$C:$C,$A8,'Daily Plan'!$A:$A,Q$1) | R8: =SUMIFS('Daily Plan'!$H:$H,'Daily Plan'!$C:$C,$A8,'Daily Plan'!$A:$A,R$1) | S8: =SUMIFS('Daily Plan'!$H:$H,'Daily Plan'!$C:$C,$A8,'Daily Plan'!$A:$A,S$1) | T8: =SUMIFS('Daily Plan'!$H:$H,'Daily Plan'!$C:$C,$A8,'Daily Plan'!$A:$A,T$1) | ... FS8: =SUMIFS('Daily Plan'!$H:$H,'Daily Plan'!$C:$C,$A8,'Daily Plan'!$A:$A,FS$1)
A9: VAL-2 | B9: 校验 | C9: 中间数据校验 | D9: 46223 | E9: 46227 | F9: pending | G9: =SUMIF('Daily Plan'!$C:$C,A9,'Daily Plan'!$H:$H) | H9: =SUMIF('Daily Plan'!$C:$C,A9,'Daily Plan'!$I:$I) | I9: =MAX(G9-H9,0) | J9: =IF(G9=0,IF(F9="done",1,0),H9/G9) | K9: VAL-1 | L9: 每日中间表校验报告 | M9: =SUMIFS('Daily Plan'!$H:$H,'Daily Plan'!$C:$C,$A9,'Daily Plan'!$A:$A,M$1) | N9: =SUMIFS('Daily Plan'!$H:$H,'Daily Plan'!$C:$C,$A9,'Daily Plan'!$A:$A,N$1) | O9: =SUMIFS('Daily Plan'!$H:$H,'Daily Plan'!$C:$C,$A9,'Daily Plan'!$A:$A,O$1) | P9: =SUMIFS('Daily Plan'!$H:$H,'Daily Plan'!$C:$C,$A9,'Daily Plan'!$A:$A,P$1) | Q9: =SUMIFS('Daily Plan'!$H:$H,'Daily Plan'!$C:$C,$A9,'Daily Plan'!$A:$A,Q$1) | R9: =SUMIFS('Daily Plan'!$H:$H,'Daily Plan'!$C:$C,$A9,'Daily Plan'!$A:$A,R$1) | S9: =SUMIFS('Daily Plan'!$H:$H,'Daily Plan'!$C:$C,$A9,'Daily Plan'!$A:$A,S$1) | T9: =SUMIFS('Daily Plan'!$H:$H,'Daily Plan'!$C:$C,$A9,'Daily Plan'!$A:$A,T$1) | ... FS9: =SUMIFS('Daily Plan'!$H:$H,'Daily Plan'!$C:$C,$A9,'Daily Plan'!$A:$A,FS$1)
A10: TEST-1 | B10: 测试 | C10: E2E 网络构建 | D10: 46230 | E10: 46248 | F10: pending | G10: =SUMIF('Daily Plan'!$C:$C,A10,'Daily Plan'!$H:$H) | H10: =SUMIF('Daily Plan'!$C:$C,A10,'Daily Plan'!$I:$I) | I10: =MAX(G10-H10,0) | J10: =IF(G10=0,IF(F10="done",1,0),H10/G10) | K10: MLE/VAL | L10: 30 天 E2E 成功跑通 | M10: =SUMIFS('Daily Plan'!$H:$H,'Daily Plan'!$C:$C,$A10,'Daily Plan'!$A:$A,M$1) | N10: =SUMIFS('Daily Plan'!$H:$H,'Daily Plan'!$C:$C,$A10,'Daily Plan'!$A:$A,N$1) | O10: =SUMIFS('Daily Plan'!$H:$H,'Daily Plan'!$C:$C,$A10,'Daily Plan'!$A:$A,O$1) | P10: =SUMIFS('Daily Plan'!$H:$H,'Daily Plan'!$C:$C,$A10,'Daily Plan'!$A:$A,P$1) | Q10: =SUMIFS('Daily Plan'!$H:$H,'Daily Plan'!$C:$C,$A10,'Daily Plan'!$A:$A,Q$1) | R10: =SUMIFS('Daily Plan'!$H:$H,'Daily Plan'!$C:$C,$A10,'Daily Plan'!$A:$A,R$1) | S10: =SUMIFS('Daily Plan'!$H:$H,'Daily Plan'!$C:$C,$A10,'Daily Plan'!$A:$A,S$1) | T10: =SUMIFS('Daily Plan'!$H:$H,'Daily Plan'!$C:$C,$A10,'Daily Plan'!$A:$A,T$1) | ... FS10: =SUMIFS('Daily Plan'!$H:$H,'Daily Plan'!$C:$C,$A10,'Daily Plan'!$A:$A,FS$1)
A11: DOC-2 | B11: 文档 | C11: 历史回测文档 | D11: 46251 | E11: 46262 | F11: pending | G11: =SUMIF('Daily Plan'!$C:$C,A11,'Daily Plan'!$H:$H) | H11: =SUMIF('Daily Plan'!$C:$C,A11,'Daily Plan'!$I:$I) | I11: =MAX(G11-H11,0) | J11: =IF(G11=0,IF(F11="done",1,0),H11/G11) | K11: TEST-1 | L11: simulated vs actual KPI 报告 | M11: =SUMIFS('Daily Plan'!$H:$H,'Daily Plan'!$C:$C,$A11,'Daily Plan'!$A:$A,M$1) | N11: =SUMIFS('Daily Plan'!$H:$H,'Daily Plan'!$C:$C,$A11,'Daily Plan'!$A:$A,N$1) | O11: =SUMIFS('Daily Plan'!$H:$H,'Daily Plan'!$C:$C,$A11,'Daily Plan'!$A:$A,O$1) | P11: =SUMIFS('Daily Plan'!$H:$H,'Daily Plan'!$C:$C,$A11,'Daily Plan'!$A:$A,P$1) | Q11: =SUMIFS('Daily Plan'!$H:$H,'Daily Plan'!$C:$C,$A11,'Daily Plan'!$A:$A,Q$1) | R11: =SUMIFS('Daily Plan'!$H:$H,'Daily Plan'!$C:$C,$A11,'Daily Plan'!$A:$A,R$1) | S11: =SUMIFS('Daily Plan'!$H:$H,'Daily Plan'!$C:$C,$A11,'Daily Plan'!$A:$A,S$1) | T11: =SUMIFS('Daily Plan'!$H:$H,'Daily Plan'!$C:$C,$A11,'Daily Plan'!$A:$A,T$1) | ... FS11: =SUMIFS('Daily Plan'!$H:$H,'Daily Plan'!$C:$C,$A11,'Daily Plan'!$A:$A,FS$1)
A12: DOC-3 | B12: 文档 | C12: trade-off 分析 | D12: 46265 | E12: 46276 | F12: pending | G12: =SUMIF('Daily Plan'!$C:$C,A12,'Daily Plan'!$H:$H) | H12: =SUMIF('Daily Plan'!$C:$C,A12,'Daily Plan'!$I:$I) | I12: =MAX(G12-H12,0) | J12: =IF(G12=0,IF(F12="done",1,0),H12/G12) | K12: TEST-1 | L12: cost/cash/service 报告 | M12: =SUMIFS('Daily Plan'!$H:$H,'Daily Plan'!$C:$C,$A12,'Daily Plan'!$A:$A,M$1) | N12: =SUMIFS('Daily Plan'!$H:$H,'Daily Plan'!$C:$C,$A12,'Daily Plan'!$A:$A,N$1) | O12: =SUMIFS('Daily Plan'!$H:$H,'Daily Plan'!$C:$C,$A12,'Daily Plan'!$A:$A,O$1) | P12: =SUMIFS('Daily Plan'!$H:$H,'Daily Plan'!$C:$C,$A12,'Daily Plan'!$A:$A,P$1) | Q12: =SUMIFS('Daily Plan'!$H:$H,'Daily Plan'!$C:$C,$A12,'Daily Plan'!$A:$A,Q$1) | R12: =SUMIFS('Daily Plan'!$H:$H,'Daily Plan'!$C:$C,$A12,'Daily Plan'!$A:$A,R$1) | S12: =SUMIFS('Daily Plan'!$H:$H,'Daily Plan'!$C:$C,$A12,'Daily Plan'!$A:$A,S$1) | T12: =SUMIFS('Daily Plan'!$H:$H,'Daily Plan'!$C:$C,$A12,'Daily Plan'!$A:$A,T$1) | ... FS12: =SUMIFS('Daily Plan'!$H:$H,'Daily Plan'!$C:$C,$A12,'Daily Plan'!$A:$A,FS$1)
A13: DOC-4 | B13: 文档 | C13: PG 数据分布 | D13: 46279 | E13: 46290 | F13: pending | G13: =SUMIF('Daily Plan'!$C:$C,A13,'Daily Plan'!$H:$H) | H13: =SUMIF('Daily Plan'!$C:$C,A13,'Daily Plan'!$I:$I) | I13: =MAX(G13-H13,0) | J13: =IF(G13=0,IF(F13="done",1,0),H13/G13) | K13: P0 | L13: PG 数据分布报告 | M13: =SUMIFS('Daily Plan'!$H:$H,'Daily Plan'!$C:$C,$A13,'Daily Plan'!$A:$A,M$1) | N13: =SUMIFS('Daily Plan'!$H:$H,'Daily Plan'!$C:$C,$A13,'Daily Plan'!$A:$A,N$1) | O13: =SUMIFS('Daily Plan'!$H:$H,'Daily Plan'!$C:$C,$A13,'Daily Plan'!$A:$A,O$1) | P13: =SUMIFS('Daily Plan'!$H:$H,'Daily Plan'!$C:$C,$A13,'Daily Plan'!$A:$A,P$1) | Q13: =SUMIFS('Daily Plan'!$H:$H,'Daily Plan'!$C:$C,$A13,'Daily Plan'!$A:$A,Q$1) | R13: =SUMIFS('Daily Plan'!$H:$H,'Daily Plan'!$C:$C,$A13,'Daily Plan'!$A:$A,R$1) | S13: =SUMIFS('Daily Plan'!$H:$H,'Daily Plan'!$C:$C,$A13,'Daily Plan'!$A:$A,S$1) | T13: =SUMIFS('Daily Plan'!$H:$H,'Daily Plan'!$C:$C,$A13,'Daily Plan'!$A:$A,T$1) | ... FS13: =SUMIFS('Daily Plan'!$H:$H,'Daily Plan'!$C:$C,$A13,'Daily Plan'!$A:$A,FS$1)
A14: DOC-1 | B14: 文档 | C14: scope/problem/success criteria | D14: 46293 | E14: 46304 | F14: pending | G14: =SUMIF('Daily Plan'!$C:$C,A14,'Daily Plan'!$H:$H) | H14: =SUMIF('Daily Plan'!$C:$C,A14,'Daily Plan'!$I:$I) | I14: =MAX(G14-H14,0) | J14: =IF(G14=0,IF(F14="done",1,0),H14/G14) | K14: 所有阶段 | L14: 最终范围与成功标准 | M14: =SUMIFS('Daily Plan'!$H:$H,'Daily Plan'!$C:$C,$A14,'Daily Plan'!$A:$A,M$1) | N14: =SUMIFS('Daily Plan'!$H:$H,'Daily Plan'!$C:$C,$A14,'Daily Plan'!$A:$A,N$1) | O14: =SUMIFS('Daily Plan'!$H:$H,'Daily Plan'!$C:$C,$A14,'Daily Plan'!$A:$A,O$1) | P14: =SUMIFS('Daily Plan'!$H:$H,'Daily Plan'!$C:$C,$A14,'Daily Plan'!$A:$A,P$1) | Q14: =SUMIFS('Daily Plan'!$H:$H,'Daily Plan'!$C:$C,$A14,'Daily Plan'!$A:$A,Q$1) | R14: =SUMIFS('Daily Plan'!$H:$H,'Daily Plan'!$C:$C,$A14,'Daily Plan'!$A:$A,R$1) | S14: =SUMIFS('Daily Plan'!$H:$H,'Daily Plan'!$C:$C,$A14,'Daily Plan'!$A:$A,S$1) | T14: =SUMIFS('Daily Plan'!$H:$H,'Daily Plan'!$C:$C,$A14,'Daily Plan'!$A:$A,T$1) | ... FS14: =SUMIFS('Daily Plan'!$H:$H,'Daily Plan'!$C:$C,$A14,'Daily Plan'!$A:$A,FS$1)
A15: CDP-2 | B15: 代码设计 | C15: 硬编码参数清理 | F15: done | G15: =SUMIF('Daily Plan'!$C:$C,A15,'Daily Plan'!$H:$H) | H15: =SUMIF('Daily Plan'!$C:$C,A15,'Daily Plan'!$I:$I) | I15: =MAX(G15-H15,0) | J15: =IF(G15=0,IF(F15="done",1,0),H15/G15) | K15: 无 | L15: 已完成，无新增计划工时 | M15: =SUMIFS('Daily Plan'!$H:$H,'Daily Plan'!$C:$C,$A15,'Daily Plan'!$A:$A,M$1) | N15: =SUMIFS('Daily Plan'!$H:$H,'Daily Plan'!$C:$C,$A15,'Daily Plan'!$A:$A,N$1) | O15: =SUMIFS('Daily Plan'!$H:$H,'Daily Plan'!$C:$C,$A15,'Daily Plan'!$A:$A,O$1) | P15: =SUMIFS('Daily Plan'!$H:$H,'Daily Plan'!$C:$C,$A15,'Daily Plan'!$A:$A,P$1) | Q15: =SUMIFS('Daily Plan'!$H:$H,'Daily Plan'!$C:$C,$A15,'Daily Plan'!$A:$A,Q$1) | R15: =SUMIFS('Daily Plan'!$H:$H,'Daily Plan'!$C:$C,$A15,'Daily Plan'!$A:$A,R$1) | S15: =SUMIFS('Daily Plan'!$H:$H,'Daily Plan'!$C:$C,$A15,'Daily Plan'!$A:$A,S$1) | T15: =SUMIFS('Daily Plan'!$H:$H,'Daily Plan'!$C:$C,$A15,'Daily Plan'!$A:$A,T$1) | ... FS15: =SUMIFS('Daily Plan'!$H:$H,'Daily Plan'!$C:$C,$A15,'Daily Plan'!$A:$A,FS$1)
A16: CDP-3 | B16: 代码设计 | C16: 死代码与注释块清理 | F16: done | G16: =SUMIF('Daily Plan'!$C:$C,A16,'Daily Plan'!$H:$H) | H16: =SUMIF('Daily Plan'!$C:$C,A16,'Daily Plan'!$I:$I) | I16: =MAX(G16-H16,0) | J16: =IF(G16=0,IF(F16="done",1,0),H16/G16) | K16: 无 | L16: 已完成，无新增计划工时 | M16: =SUMIFS('Daily Plan'!$H:$H,'Daily Plan'!$C:$C,$A16,'Daily Plan'!$A:$A,M$1) | N16: =SUMIFS('Daily Plan'!$H:$H,'Daily Plan'!$C:$C,$A16,'Daily Plan'!$A:$A,N$1) | O16: =SUMIFS('Daily Plan'!$H:$H,'Daily Plan'!$C:$C,$A16,'Daily Plan'!$A:$A,O$1) | P16: =SUMIFS('Daily Plan'!$H:$H,'Daily Plan'!$C:$C,$A16,'Daily Plan'!$A:$A,P$1) | Q16: =SUMIFS('Daily Plan'!$H:$H,'Daily Plan'!$C:$C,$A16,'Daily Plan'!$A:$A,Q$1) | R16: =SUMIFS('Daily Plan'!$H:$H,'Daily Plan'!$C:$C,$A16,'Daily Plan'!$A:$A,R$1) | S16: =SUMIFS('Daily Plan'!$H:$H,'Daily Plan'!$C:$C,$A16,'Daily Plan'!$A:$A,S$1) | T16: =SUMIFS('Daily Plan'!$H:$H,'Daily Plan'!$C:$C,$A16,'Daily Plan'!$A:$A,T$1) | ... FS16: =SUMIFS('Daily Plan'!$H:$H,'Daily Plan'!$C:$C,$A16,'Daily Plan'!$A:$A,FS$1)
A17: FINAL | B17: 收尾 | C17: 最终验收 | D17: 46307 | E17: 46310 | F17: pending | G17: =SUMIF('Daily Plan'!$C:$C,A17,'Daily Plan'!$H:$H) | H17: =SUMIF('Daily Plan'!$C:$C,A17,'Daily Plan'!$I:$I) | I17: =MAX(G17-H17,0) | J17: =IF(G17=0,IF(F17="done",1,0),H17/G17) | K17: 全部任务 | L17: sign-off 完成 | M17: =SUMIFS('Daily Plan'!$H:$H,'Daily Plan'!$C:$C,$A17,'Daily Plan'!$A:$A,M$1) | N17: =SUMIFS('Daily Plan'!$H:$H,'Daily Plan'!$C:$C,$A17,'Daily Plan'!$A:$A,N$1) | O17: =SUMIFS('Daily Plan'!$H:$H,'Daily Plan'!$C:$C,$A17,'Daily Plan'!$A:$A,O$1) | P17: =SUMIFS('Daily Plan'!$H:$H,'Daily Plan'!$C:$C,$A17,'Daily Plan'!$A:$A,P$1) | Q17: =SUMIFS('Daily Plan'!$H:$H,'Daily Plan'!$C:$C,$A17,'Daily Plan'!$A:$A,Q$1) | R17: =SUMIFS('Daily Plan'!$H:$H,'Daily Plan'!$C:$C,$A17,'Daily Plan'!$A:$A,R$1) | S17: =SUMIFS('Daily Plan'!$H:$H,'Daily Plan'!$C:$C,$A17,'Daily Plan'!$A:$A,S$1) | T17: =SUMIFS('Daily Plan'!$H:$H,'Daily Plan'!$C:$C,$A17,'Daily Plan'!$A:$A,T$1) | ... FS17: =SUMIFS('Daily Plan'!$H:$H,'Daily Plan'!$C:$C,$A17,'Daily Plan'!$A:$A,FS$1)
A20: 工时口径 | B20: 默认每个 Daily Plan 行 = 10h；可在 Daily Plan 的计划工时/已完成工时列手动调整，Progress Tracker 与 Hourly Gantt 将按公式汇总。
A22: 启动 | B22: planned hours > 0
A23: 工程 | B23: planned hours > 0
A24: 校验 | B24: planned hours > 0
A25: 测试 | B25: planned hours > 0
A26: 文档 | B26: planned hours > 0
A27: 代码设计 | B27: planned hours > 0
A28: 收尾 | B28: planned hours > 0

Sheet Acceptance Criteria
A1: 任务 | B1: 必须满足的验收标准
A2: M1 周→日订单生成 | B2: 周总量守恒；拆分只落在有效下单日；date=require_date；simulation_date=order_date；AO/normal 逻辑一致；随机数可复现；M3/M5 不受影响
A3: M4 多产线排程 | B3: 一个 SKU 可多线生产；产能不超；换产逻辑正确；边界 case 通过
A4: filtered DataFrame 优化 | B4: 无 chained assignment warning；无视图/副本不确定行为
A5: 避免逐日 append | B5: 热点路径不再循环 append；性能 benchmark 有改善
A6: 输入校验 | B6: 缺字段、错类型、非法范围、网络不一致均可识别
A7: 中间校验 | B7: 每日关键中间表可校验；错误定位到表/字段/日期
A8: E2E 测试网络 | B8: 30 天仿真稳定跑通；库存平衡；关键 KPI 可解释
A9: 回测文档 | B9: simulated vs actual KPI 有图表、有偏差解释
A10: trade-off 分析 | B10: cost/cash/service 指标定义清晰，场景结果可复现
A11: PG 分布分析 | B11: 主要字段分布、异常、建模影响均记录
A12: scope 文档 | B12: 范围、问题、成功标准、非目标明确
A13: 最终验收 | B13: 代码、验证、测试、文档、风险关闭全部完成

Sheet Performance Gates
A1: 机制 | B1: 说明
A2: 基线先行 | B2: 每项优化前先记录原始耗时、行数、输出 hash
A3: 向量化优先 | B3: DataFrame 构造使用批量生成，不逐日 append
A4: 缓存重复计算 | B4: 周→日预测、静态配置、索引映射只算一次
A5: Numba/NumPy 加速 | B5: 对存在顺序依赖的循环，用 JIT/数组方式加速
A6: 回归对比 | B6: 每项改动后对比 OrderLog、SupplyDemandLog、ShipmentLog
A7: 性能门禁 | B7: 优化后不得慢于基线；核心模块需记录平均耗时
A8: fallback 开关 | B8: 高风险优化必须保留旧逻辑开关回退
